Workbook

Sheet Supuestos
A1: Crédito en USD para maquinaria amarilla – Supuestos
A3: Concepto | B3: Valor | C3: Fuente / nota
A4: Valor de la maquinaria (COP) | B4: 400000000
A5: Aporte inicial de los inversionistas (%) | B5: 0.1
A6: Aporte inicial (COP) | B6: =B4*B5 -> 40000000 | C6: Cálculo
A7: Monto a financiar (COP) – 90 % | B7: =B4-B6 -> 360000000 | C7: Cálculo
A8: TRM (COP por USD) | B8: 3174.67 | C8: TRM vigente del 17 al 19 de oct. de 2026, certificada por la Superfinanciera; consultada el 18/10/2026 (ver fuentes abajo)
A9: Monto a financiar (USD) | B9: =B7/B8 -> 113397.61
A10: Plazo (años) | B10: 10
A11: Pagos por año | B11: 4
A12: Número de cuotas | B12: =B10*B11 -> 40 | C12: Cálculo
A13: Tasa base: Prime Rate (% anual) | B13: 0.07 | C13: 7,00 % vigente desde el 17 de sept. de 2026 (Prime de U.S. Bank y WSJ Prime); ver fuentes abajo
A14: Margen máximo SBA 7(a) (puntos sobre Prime) | B14: 0.06 | C14: Tope de Prime + 6,0 pp para préstamos de USD 50.001 a 250.000, igual para tasa fija y variable (ver fuentes abajo)
A15: Tasa nominal anual FIJA (Prime + margen) | B15: =B13+B14 -> 0.13 | C15: Cotización: tasa fija nominal anual, pagadera trimestre vencido. El tope se fija con el Prime vigente al aprobar el crédito y no cambia durante los 10 años
A16: Tasa trimestral (nominal anual / 4) | B16: =B15/B11 -> 0.0325 | C16: Cálculo
A17: Tasa efectiva anual equivalente | B17: =(1+B16)^B11-1 -> 0.13647593 | C17: Cálculo: (1 + i trimestral)^4 − 1
A18: Cuota trimestral constante (USD) | B18: =PMT(B16,B12,-B9) -> 5106.0609 | C18: Sistema francés: P·i / (1 − (1+i)^−n)
A19: Total pagado en el plazo (USD) | B19: =B18*B12 -> 204242.44 | C19: Cálculo
A20: Total de intereses (USD) | B20: =B19-B9 -> 90844.824 | C20: Cálculo
A23: Fuentes, fecha de consulta y forma de cotización
A24: Dato | B24: Valor | C24: Fuente (URL) | E24: Forma de cotización
A25: Prime Rate | B25: 7,00 % | C25: https://primerates.com/prime-rate-rises-7-percent-fed-first-hike-since-july-2023/ ; https://s203.q4cdn.com/711684571/files/doc_news/U-S--Bank-Increases-Prime-Lending-Rate-to-7-00-Percent-2026.pdf | E25: Tasa base anual; vigente desde el 17/09/2026 (antes 6,75 %). Cambia cuando la Fed mueve su tasa
A26: Tope SBA 7(a), préstamos de USD 50.001 a 250.000 | B26: Prime + 6,0 % (13,00 % con Prime de 7 %) | C26: https://www.sba.gov/es/node/8664 (Terms, conditions, and eligibility) ; https://www.nerdwallet.com/article/small-business/sba-loan-rates (topes fijos y variables, act. 16/09/2026) | E26: Tope regulatorio de la SBA; el banco puede cotizar por debajo. Tasa fija o variable
A27: TRM COP/USD | B27: 3.174,67 | C27: https://dolar.wilkinsonpc.com.co/ (reproduce la TRM certificada por la Superfinanciera; verificar en https://www.superfinanciera.gov.co) | E27: COP por 1 USD; vigente del 17 al 19 de oct. de 2026
A28: SOFR (referencia, no usada en el cálculo) | B28: 3,89 % (15/10/2026) | C28: https://fred.stlouisfed.org/series/SOFR | E28: Tasa overnight publicada por la NY Fed; promedio de 30 días: 3,87449 % (16/10/2026)
A29: Comisión de garantía SBA 7(a), año fiscal 2027 | B29: 2 % de la parte garantizada (85 %) | C29: https://colemanreport.com/sba-hot-topic-tuesday-grocery-manufacturing-and-rural-businesses-get-new-fy-2027-fee-relief/ ; https://www.nerdwallet.com/business/loans/learn/sba-7a-loan (garantía de 85 % hasta USD 150.000) | E29: Pago único al desembolso para préstamos de USD 150.000 o menos aprobados entre el 01/10/2026 y el 30/09/2027
A30: Tasa SBA 504, debenture de 10 años | B30: 6,60 % (venta del 10/09/2026) | C30: https://www.crowdfundedwealth.com/articles/sba-504-loan-rates-2026 (datos de SomerCor CDC) | E30: Tasa fija efectiva con comisiones incluidas; solo cubre el 40 % del proyecto
A31: Entidad prestamista: U.S. Bank | B31: SBA 7(a) y 504; sin cargos propios de procesamiento | C31: https://www.usbank.com/business-banking/business-lending/sba-loans.html ; https://www.usbank.com/about-us-bank/news-and-stories/article-library/us-bank-boosts-sba-lending-to-a-record-943-million-in-7a-loans.html | E31: 7(a) para equipo hasta 10 años, con opción de tasa fija o variable
A32: Requisito de propiedad de la SBA | B32: 100 % de dueños ciudadanos o nacionales de EE. UU. | C32: https://www.naggl.org/procedural-notice-revising-sop-50-10-8-for-new-citizenship-and-residency-requirements/ | E32: Aviso 5000-876626, vigente desde el 01/03/2026 para 7(a) y 504

Sheet Amortización
A1: Tabla de amortización – Sistema francés, cuotas trimestrales constantes (USD)
A2: Todos los valores se calculan con las celdas de la hoja Supuestos.
A4: Trimestre | B4: Año | C4: Saldo inicial (USD) | D4: Cuota (USD) | E4: Interés (USD) | F4: Abono a capital (USD) | G4: Saldo final (USD)
A5: 1 | B5: =ROUNDUP(A5/Supuestos!$B$11,0) -> 1 | C5: =Supuestos!$B$9 -> 113397.61 | D5: =Supuestos!$B$18 -> 5106.0609 | E5: =C5*Supuestos!$B$16 -> 3685.4224 | F5: =D5-E5 -> 1420.6385 | G5: =C5-F5 -> 111976.97
A6: 2 | B6: =ROUNDUP(A6/Supuestos!$B$11,0) -> 1 | C6: =G5 -> 111976.97 | D6: =Supuestos!$B$18 -> 5106.0609 | E6: =C6*Supuestos!$B$16 -> 3639.2517 | F6: =D6-E6 -> 1466.8092 | G6: =C6-F6 -> 110510.17
A7: 3 | B7: =ROUNDUP(A7/Supuestos!$B$11,0) -> 1 | C7: =G6 -> 110510.17 | D7: =Supuestos!$B$18 -> 5106.0609 | E7: =C7*Supuestos!$B$16 -> 3591.5804 | F7: =D7-E7 -> 1514.4805 | G7: =C7-F7 -> 108995.68
A8: 4 | B8: =ROUNDUP(A8/Supuestos!$B$11,0) -> 1 | C8: =G7 -> 108995.68 | D8: =Supuestos!$B$18 -> 5106.0609 | E8: =C8*Supuestos!$B$16 -> 3542.3598 | F8: =D8-E8 -> 1563.7012 | G8: =C8-F8 -> 107431.98
A9: 5 | B9: =ROUNDUP(A9/Supuestos!$B$11,0) -> 2 | C9: =G8 -> 107431.98 | D9: =Supuestos!$B$18 -> 5106.0609 | E9: =C9*Supuestos!$B$16 -> 3491.5395 | F9: =D9-E9 -> 1614.5215 | G9: =C9-F9 -> 105817.46
A10: 6 | B10: =ROUNDUP(A10/Supuestos!$B$11,0) -> 2 | C10: =G9 -> 105817.46 | D10: =Supuestos!$B$18 -> 5106.0609 | E10: =C10*Supuestos!$B$16 -> 3439.0675 | F10: =D10-E10 -> 1666.9934 | G10: =C10-F10 -> 104150.47
A11: 7 | B11: =ROUNDUP(A11/Supuestos!$B$11,0) -> 2 | C11: =G10 -> 104150.47 | D11: =Supuestos!$B$18 -> 5106.0609 | E11: =C11*Supuestos!$B$16 -> 3384.8902 | F11: =D11-E11 -> 1721.1707 | G11: =C11-F11 -> 102429.3
A12: 8 | B12: =ROUNDUP(A12/Supuestos!$B$11,0) -> 2 | C12: =G11 -> 102429.3 | D12: =Supuestos!$B$18 -> 5106.0609 | E12: =C12*Supuestos!$B$16 -> 3328.9522 | F12: =D12-E12 -> 1777.1087 | G12: =C12-F12 -> 100652.19
A13: 9 | B13: =ROUNDUP(A13/Supuestos!$B$11,0) -> 3 | C13: =G12 -> 100652.19 | D13: =Supuestos!$B$18 -> 5106.0609 | E13: =C13*Supuestos!$B$16 -> 3271.1962 | F13: =D13-E13 -> 1834.8648 | G13: =C13-F13 -> 98817.324
A14: 10 | B14: =ROUNDUP(A14/Supuestos!$B$11,0) -> 3 | C14: =G13 -> 98817.324 | D14: =Supuestos!$B$18 -> 5106.0609 | E14: =C14*Supuestos!$B$16 -> 3211.563 | F14: =D14-E14 -> 1894.4979 | G14: =C14-F14 -> 96922.827
A15: 11 | B15: =ROUNDUP(A15/Supuestos!$B$11,0) -> 3 | C15: =G14 -> 96922.827 | D15: =Supuestos!$B$18 -> 5106.0609 | E15: =C15*Supuestos!$B$16 -> 3149.9919 | F15: =D15-E15 -> 1956.0691 | G15: =C15-F15 -> 94966.758
A16: 12 | B16: =ROUNDUP(A16/Supuestos!$B$11,0) -> 3 | C16: =G15 -> 94966.758 | D16: =Supuestos!$B$18 -> 5106.0609 | E16: =C16*Supuestos!$B$16 -> 3086.4196 | F16: =D16-E16 -> 2019.6413 | G16: =C16-F16 -> 92947.116
A17: 13 | B17: =ROUNDUP(A17/Supuestos!$B$11,0) -> 4 | C17: =G16 -> 92947.116 | D17: =Supuestos!$B$18 -> 5106.0609 | E17: =C17*Supuestos!$B$16 -> 3020.7813 | F17: =D17-E17 -> 2085.2796 | G17: =C17-F17 -> 90861.837
... A44: 40 | B44: =ROUNDUP(A44/Supuestos!$B$11,0) -> 10 | C44: =G43 -> 4945.3375 | D44: =Supuestos!$B$18 -> 5106.0609 | E44: =C44*Supuestos!$B$16 -> 160.72347 | F44: =D44-E44 -> 4945.3375 | G44: =C44-F44 -> -1.3187673e-10
A45: Total | D45: =SUM(D5:D44) -> 204242.44 | E45: =SUM(E5:E44) -> 90844.824 | F45: =SUM(F5:F44) -> 113397.61
G47: =ROUND(G44,2) -> 0
G48: =ROUND(F45-Supuestos!B9,2) -> 0

Sheet A.3 Conversión
A1: A.3 Conversión del crédito a pesos colombianos
A2: Cada cuota en USD (constante) se multiplica por la TRM de su trimestre. Primero con la TRM spot de la fecha de valoración y luego con las trayectorias de la hoja «Trayectorias TRM».
A3: TRM spot (fecha de valoración) | B3: =Supuestos!B8 -> 3174.67
A4: Cuota trimestral (USD) | B4: =Supuestos!B18 -> 5106.0609
A5: Monto recibido (COP) | B5: =Supuestos!B7 -> 360000000
A7: Trimestre | B7: Año | C7: Cuota USD | D7: Interés USD | E7: Abono capital USD | F7: Cuota COP – spot | G7: Cuota COP – base | H7: Cuota COP – peso fuerte | I7: Cuota COP – peso débil | J7: Cuota COP – sim. P5 | K7: Cuota COP – sim. P50 | L7: Cuota COP – sim. P95 | M7: Cuota COP – sim. media | N7: Base: interés a TRM spot | O7: Base: capital a TRM spot | P7: Base: efecto cambiario sobre interés | Q7: Base: efecto cambiario sobre capital | R7: Cambio de la cuota base vs trimestre anterior
A8: 1 | B8: =Amortización!B5 -> 1 | C8: =Amortización!D5 -> 5106.0609 | D8: =Amortización!E5 -> 3685.4224 | E8: =Amortización!F5 -> 1420.6385 | F8: =$C8*'Trayectorias TRM'!C6 -> 16210058 | G8: =$C8*'Trayectorias TRM'!D6 -> 16457121 | H8: =$C8*'Trayectorias TRM'!E6 -> 16143047 | I8: =$C8*'Trayectorias TRM'!F6 -> 16836488 | J8: =$C8*'Trayectorias TRM'!G6 -> 15272255 | K8: =$C8*'Trayectorias TRM'!I6 -> 16477735 | L8: =$C8*'Trayectorias TRM'!K6 -> 17784897 | M8: =$C8*'Trayectorias TRM'!L6 -> 16497255 | N8: =D8*$B$3 -> 11700000 | O8: =E8*$B$3 -> 4510058.4 | P8: =D8*('Trayectorias TRM'!D6-$B$3) -> 178323.27 | Q8: =E8*('Trayectorias TRM'!D6-$B$3) -> 68739.176 | R8: =G8-F8 -> 247062.44
A9: 2 | B9: =Amortización!B6 -> 1 | C9: =Amortización!D6 -> 5106.0609 | D9: =Amortización!E6 -> 3639.2517 | E9: =Amortización!F6 -> 1466.8092 | F9: =$C9*'Trayectorias TRM'!C7 -> 16210058 | G9: =$C9*'Trayectorias TRM'!D7 -> 16707949 | H9: =$C9*'Trayectorias TRM'!E7 -> 16076313 | I9: =$C9*'Trayectorias TRM'!F7 -> 17487126 | J9: =$C9*'Trayectorias TRM'!G7 -> 15150281 | K9: =$C9*'Trayectorias TRM'!I7 -> 16736022 | L9: =$C9*'Trayectorias TRM'!K7 -> 18525210 | M9: =$C9*'Trayectorias TRM'!L7 -> 16774908 | N9: =D9*$B$3 -> 11553423 | O9: =E9*$B$3 -> 4656635.3 | P9: =D9*('Trayectorias TRM'!D7-$B$3) -> 354862.32 | Q9: =E9*('Trayectorias TRM'!D7-$B$3) -> 143028.12 | R9: =G9-G8 -> 250828
A10: 3 | B10: =Amortización!B7 -> 1 | C10: =Amortización!D7 -> 5106.0609 | D10: =Amortización!E7 -> 3591.5804 | E10: =Amortización!F7 -> 1514.4805 | F10: =$C10*'Trayectorias TRM'!C8 -> 16210058 | G10: =$C10*'Trayectorias TRM'!D8 -> 16962600 | H10: =$C10*'Trayectorias TRM'!E8 -> 16009854 | I10: =$C10*'Trayectorias TRM'!F8 -> 18162908 | J10: =$C10*'Trayectorias TRM'!G8 -> 15259964 | K10: =$C10*'Trayectorias TRM'!I8 -> 16977448 | L10: =$C10*'Trayectorias TRM'!K8 -> 19069517 | M10: =$C10*'Trayectorias TRM'!L8 -> 17047665 | N10: =D10*$B$3 -> 11402082 | O10: =E10*$B$3 -> 4807976 | P10: =D10*('Trayectorias TRM'!D8-$B$3) -> 529334.24 | Q10: =E10*('Trayectorias TRM'!D8-$B$3) -> 223207.15 | R10: =G10-G9 -> 254650.94
A11: 4 | B11: =Amortización!B8 -> 1 | C11: =Amortización!D8 -> 5106.0609 | D11: =Amortización!E8 -> 3542.3598 | E11: =Amortización!F8 -> 1563.7012 | F11: =$C11*'Trayectorias TRM'!C9 -> 16210058 | G11: =$C11*'Trayectorias TRM'!D9 -> 17221132 | H11: =$C11*'Trayectorias TRM'!E9 -> 15943670 | I11: =$C11*'Trayectorias TRM'!F9 -> 18864805 | J11: =$C11*'Trayectorias TRM'!G9 -> 15515505 | K11: =$C11*'Trayectorias TRM'!I9 -> 17212007 | L11: =$C11*'Trayectorias TRM'!K9 -> 19562390 | M11: =$C11*'Trayectorias TRM'!L9 -> 17319921 | N11: =D11*$B$3 -> 11245823 | O11: =E11*$B$3 -> 4964235.2 | P11: =D11*('Trayectorias TRM'!D9-$B$3) -> 701438.21 | Q11: =E11*('Trayectorias TRM'!D9-$B$3) -> 309635.33 | R11: =G11-G10 -> 258532.16
A12: 5 | B12: =Amortización!B9 -> 2 | C12: =Amortización!D9 -> 5106.0609 | D12: =Amortización!E9 -> 3491.5395 | E12: =Amortización!F9 -> 1614.5215 | F12: =$C12*'Trayectorias TRM'!C10 -> 16210058 | G12: =$C12*'Trayectorias TRM'!D10 -> 17303022 | H12: =$C12*'Trayectorias TRM'!E10 -> 16019486 | I12: =$C12*'Trayectorias TRM'!F10 -> 18954511 | J12: =$C12*'Trayectorias TRM'!G10 -> 14885803 | K12: =$C12*'Trayectorias TRM'!I10 -> 17323662 | L12: =$C12*'Trayectorias TRM'!K10 -> 20416124 | M12: =$C12*'Trayectorias TRM'!L10 -> 17443286 | N12: =D12*$B$3 -> 11084486 | O12: =E12*$B$3 -> 5125572.8 | P12: =D12*('Trayectorias TRM'!D10-$B$3) -> 747371.77 | Q12: =E12*('Trayectorias TRM'!D10-$B$3) -> 345591.9 | R12: =G12-G11 -> 81890.131
A13: 6 | B13: =Amortización!B10 -> 2 | C13: =Amortización!D10 -> 5106.0609 | D13: =Amortización!E10 -> 3439.0675 | E13: =Amortización!F10 -> 1666.9934 | F13: =$C13*'Trayectorias TRM'!C11 -> 16210058 | G13: =$C13*'Trayectorias TRM'!D11 -> 17385302 | H13: =$C13*'Trayectorias TRM'!E11 -> 16095662 | I13: =$C13*'Trayectorias TRM'!F11 -> 19044644 | J13: =$C13*'Trayectorias TRM'!G11 -> 14454139 | K13: =$C13*'Trayectorias TRM'!I11 -> 17408079 | L13: =$C13*'Trayectorias TRM'!K11 -> 21166430 | M13: =$C13*'Trayectorias TRM'!L11 -> 17561634 | N13: =D13*$B$3 -> 10917904 | O13: =E13*$B$3 -> 5292153.9 | P13: =D13*('Trayectorias TRM'!D11-$B$3) -> 791557.49 | Q13: =E13*('Trayectorias TRM'!D11-$B$3) -> 383685.72 | R13: =G13-G12 -> 82279.536
A14: 7 | B14: =Amortización!B11 -> 2 | C14: =Amortización!D11 -> 5106.0609 | D14: =Amortización!E11 -> 3384.8902 | E14: =Amortización!F11 -> 1721.1707 | F14: =$C14*'Trayectorias TRM'!C12 -> 16210058 | G14: =$C14*'Trayectorias TRM'!D12 -> 17467972 | H14: =$C14*'Trayectorias TRM'!E12 -> 16172200 | I14: =$C14*'Trayectorias TRM'!F12 -> 19135205 | J14: =$C14*'Trayectorias TRM'!G12 -> 14084081 | K14: =$C14*'Trayectorias TRM'!I12 -> 17525367 | L14: =$C14*'Trayectorias TRM'!K12 -> 21933653 | M14: =$C14*'Trayectorias TRM'!L12 -> 17705404 | N14: =D14*$B$3 -> 10745909 | O14: =E14*$B$3 -> 5464148.9 | P14: =D14*('Trayectorias TRM'!D12-$B$3) -> 833891.5 | Q14: =E14*('Trayectorias TRM'!D12-$B$3) -> 424022.5 | R14: =G14-G13 -> 82670.792
A15: 8 | B15: =Amortización!B12 -> 2 | C15: =Amortización!D12 -> 5106.0609 | D15: =Amortización!E12 -> 3328.9522 | E15: =Amortización!F12 -> 1777.1087 | F15: =$C15*'Trayectorias TRM'!C13 -> 16210058 | G15: =$C15*'Trayectorias TRM'!D13 -> 17551036 | H15: =$C15*'Trayectorias TRM'!E13 -> 16249102 | I15: =$C15*'Trayectorias TRM'!F13 -> 19226197 | J15: =$C15*'Trayectorias TRM'!G13 -> 13791879 | K15: =$C15*'Trayectorias TRM'!I13 -> 17626132 | L15: =$C15*'Trayectorias TRM'!K13 -> 22555925 | M15: =$C15*'Trayectorias TRM'!L13 -> 17822281 | N15: =D15*$B$3 -> 10568325 | O15: =E15*$B$3 -> 5641733.8 | P15: =D15*('Trayectorias TRM'!D13-$B$3) -> 874265.2 | Q15: =E15*('Trayectorias TRM'!D13-$B$3) -> 466712.72 | R15: =G15-G14 -> 83063.91
A16: 9 | B16: =Amortización!B13 -> 3 | C16: =Amortización!D13 -> 5106.0609 | D16: =Amortización!E13 -> 3271.1962 | E16: =Amortización!F13 -> 1834.8648 | F16: =$C16*'Trayectorias TRM'!C14 -> 16210058 | G16: =$C16*'Trayectorias TRM'!D14 -> 17634495 | H16: =$C16*'Trayectorias TRM'!E14 -> 16326370 | I16: =$C16*'Trayectorias TRM'!F14 -> 19317622 | J16: =$C16*'Trayectorias TRM'!G14 -> 13564801 | K16: =$C16*'Trayectorias TRM'!I14 -> 17712530 | L16: =$C16*'Trayectorias TRM'!K14 -> 23134022 | M16: =$C16*'Trayectorias TRM'!L14 -> 17946940 | N16: =D16*$B$3 -> 10384968 | O16: =E16*$B$3 -> 5825090.1 | P16: =D16*('Trayectorias TRM'!D14-$B$3) -> 912564.94 | Q16: =E16*('Trayectorias TRM'!D14-$B$3) -> 511871.86 | R16: =G16-G15 -> 83458.896
A17: 10 | B17: =Amortización!B14 -> 3 | C17: =Amortización!D14 -> 5106.0609 | D17: =Amortización!E14 -> 3211.563 | E17: =Amortización!F14 -> 1894.4979 | F17: =$C17*'Trayectorias TRM'!C15 -> 16210058 | G17: =$C17*'Trayectorias TRM'!D15 -> 17718351 | H17: =$C17*'Trayectorias TRM'!E15 -> 16404005 | I17: =$C17*'Trayectorias TRM'!F15 -> 19409481 | J17: =$C17*'Trayectorias TRM'!G15 -> 13344235 | K17: =$C17*'Trayectorias TRM'!I15 -> 17806302 | L17: =$C17*'Trayectorias TRM'!K15 -> 23820800 | M17: =$C17*'Trayectorias TRM'!L15 -> 18079269 | N17: =D17*$B$3 -> 10195653 | O17: =E17*$B$3 -> 6014405.6 | P17: =D17*('Trayectorias TRM'!D15-$B$3) -> 948671.93 | Q17: =E17*('Trayectorias TRM'!D15-$B$3) -> 559620.64 | R17: =G17-G16 -> 83855.761
A18: 11 | B18: =Amortización!B15 -> 3 | C18: =Amortización!D15 -> 5106.0609 | D18: =Amortización!E15 -> 3149.9919 | E18: =Amortización!F15 -> 1956.0691 | F18: =$C18*'Trayectorias TRM'!C16 -> 16210058 | G18: =$C18*'Trayectorias TRM'!D16 -> 17802605 | H18: =$C18*'Trayectorias TRM'!E16 -> 16482010 | I18: =$C18*'Trayectorias TRM'!F16 -> 19501777 | J18: =$C18*'Trayectorias TRM'!G16 -> 13144318 | K18: =$C18*'Trayectorias TRM'!I16 -> 17861467 | L18: =$C18*'Trayectorias TRM'!K16 -> 24397435 | M18: =$C18*'Trayectorias TRM'!L16 -> 18201770 | N18: =D18*$B$3 -> 10000185 | O18: =E18*$B$3 -> 6209873.7 | P18: =D18*('Trayectorias TRM'!D16-$B$3) -> 982461.91 | Q18: =E18*('Trayectorias TRM'!D16-$B$3) -> 610085.17 | R18: =G18-G17 -> 84254.513
A19: 12 | B19: =Amortización!B16 -> 3 | C19: =Amortización!D16 -> 5106.0609 | D19: =Amortización!E16 -> 3086.4196 | E19: =Amortización!F16 -> 2019.6413 | F19: =$C19*'Trayectorias TRM'!C17 -> 16210058 | G19: =$C19*'Trayectorias TRM'!D17 -> 17887261 | H19: =$C19*'Trayectorias TRM'!E17 -> 16560385 | I19: =$C19*'Trayectorias TRM'!F17 -> 19594512 | J19: =$C19*'Trayectorias TRM'!G17 -> 12966517 | K19: =$C19*'Trayectorias TRM'!I17 -> 17936894 | L19: =$C19*'Trayectorias TRM'!K17 -> 24934328 | M19: =$C19*'Trayectorias TRM'!L17 -> 18337267 | N19: =D19*$B$3 -> 9798363.8 | O19: =E19*$B$3 -> 6411694.6 | P19: =D19*('Trayectorias TRM'!D17-$B$3) -> 1013805 | Q19: =E19*('Trayectorias TRM'!D17-$B$3) -> 663397.28 | R19: =G19-G18 -> 84655.161
A20: 13 | B20: =Amortización!B17 -> 4 | C20: =Amortización!D17 -> 5106.0609 | D20: =Amortización!E17 -> 3020.7813 | E20: =Amortización!F17 -> 2085.2796 | F20: =$C20*'Trayectorias TRM'!C18 -> 16210058 | G20: =$C20*'Trayectorias TRM'!D18 -> 17972318 | H20: =$C20*'Trayectorias TRM'!E18 -> 16639134 | I20: =$C20*'Trayectorias TRM'!F18 -> 19687688 | J20: =$C20*'Trayectorias TRM'!G18 -> 12830507 | K20: =$C20*'Trayectorias TRM'!I18 -> 18014836 | L20: =$C20*'Trayectorias TRM'!K18 -> 25515706 | M20: =$C20*'Trayectorias TRM'!L18 -> 18458646 | N20: =D20*$B$3 -> 9589983.7 | O20: =E20*$B$3 -> 6620074.7 | P20: =D20*('Trayectorias TRM'!D18-$B$3) -> 1042565.3 | Q20: =E20*('Trayectorias TRM'!D18-$B$3) -> 719694.66 | R20: =G20-G19 -> 85057.714
... A47: 40 | B47: =Amortización!B44 -> 10 | C47: =Amortización!D44 -> 5106.0609 | D47: =Amortización!E44 -> 160.72347 | E47: =Amortización!F44 -> 4945.3375 | F47: =$C47*'Trayectorias TRM'!C45 -> 16210058 | G47: =$C47*'Trayectorias TRM'!D45 -> 20428258 | H47: =$C47*'Trayectorias TRM'!E45 -> 18912892 | I47: =$C47*'Trayectorias TRM'!F45 -> 22378035 | J47: =$C47*'Trayectorias TRM'!G45 -> 10601093 | K47: =$C47*'Trayectorias TRM'!I45 -> 20511832 | L47: =$C47*'Trayectorias TRM'!K45 -> 39723545 | M47: =$C47*'Trayectorias TRM'!L45 -> 22197403 | N47: =D47*$B$3 -> 510243.97 | O47: =E47*$B$3 -> 15699814 | P47: =D47*('Trayectorias TRM'!D45-$B$3) -> 132776.25 | Q47: =E47*('Trayectorias TRM'!D45-$B$3) -> 4085423.1 | R47: =G47-G46 -> 96680.955
A48: Total | C48: =SUM(C8:C47) -> 204242.44 | D48: =SUM(D8:D47) -> 90844.824 | E48: =SUM(E8:E47) -> 113397.61 | F48: =SUM(F8:F47) -> 6.4840234e+08 | G48: =SUM(G8:G47) -> 7.4500029e+08 | H48: =SUM(H8:H47) -> 6.9155625e+08 | I48: =SUM(I8:I47) -> 8.1368134e+08 | J48: =SUM(J8:J47) -> 4.9335431e+08 | ... Q48: =SUM(Q8:Q47) -> 62098159
A51: Resumen del costo en pesos por trayectoria
A52: Concepto | B52: TRM spot | C52: Escenario base | D52: Peso fuerte | E52: Peso débil | F52: Simulación P5 | G52: Simulación P50 | H52: Simulación P95 | I52: Simulación media
A53: Total pagado (COP) | B53: =F48 -> 6.4840234e+08 | C53: =G48 -> 7.4500029e+08 | D53: =H48 -> 6.9155625e+08 | E53: =I48 -> 8.1368134e+08 | F53: =J48 -> 4.9335431e+08 | G53: =K48 -> 7.471117e+08 | H53: =L48 -> 1.1692973e+09 | I53: =M48 -> 7.7827053e+08
A54: Diferencia frente a TRM spot (COP) | B54: =B53-$B$53 -> 0 | C54: =C53-$B$53 -> 96597952 | D54: =D53-$B$53 -> 43153914 | E54: =E53-$B$53 -> 1.65279e+08 | F54: =F53-$B$53 -> -1.5504803e+08 | G54: =G53-$B$53 -> 98709368 | H54: =H53-$B$53 -> 5.2089493e+08 | I54: =I53-$B$53 -> 1.298682e+08
A55: Diferencia frente a TRM spot (%) | B55: =B53/$B$53-1 -> 0 | C55: =C53/$B$53-1 -> 0.14897841 | D55: =D53/$B$53-1 -> 0.066554224 | E55: =E53/$B$53-1 -> 0.25490192 | F55: =F53/$B$53-1 -> -0.23912318 | G55: =G53/$B$53-1 -> 0.15223475 | H55: =H53/$B$53-1 -> 0.80335141 | I55: =I53/$B$53-1 -> 0.20028953
A56: Capital valorado a TRM spot | B56: =SUM($E$8:$E$47)*$B$3 -> 3.6e+08 | C56: =SUM($E$8:$E$47)*$B$3 -> 3.6e+08 | D56: =SUM($E$8:$E$47)*$B$3 -> 3.6e+08 | E56: =SUM($E$8:$E$47)*$B$3 -> 3.6e+08 | F56: =SUM($E$8:$E$47)*$B$3 -> 3.6e+08 | G56: =SUM($E$8:$E$47)*$B$3 -> 3.6e+08 | H56: =SUM($E$8:$E$47)*$B$3 -> 3.6e+08 | I56: =SUM($E$8:$E$47)*$B$3 -> 3.6e+08
A57: Intereses valorados a TRM spot | B57: =SUM($D$8:$D$47)*$B$3 -> 2.8840234e+08 | C57: =SUM($D$8:$D$47)*$B$3 -> 2.8840234e+08 | D57: =SUM($D$8:$D$47)*$B$3 -> 2.8840234e+08 | E57: =SUM($D$8:$D$47)*$B$3 -> 2.8840234e+08 | F57: =SUM($D$8:$D$47)*$B$3 -> 2.8840234e+08 | G57: =SUM($D$8:$D$47)*$B$3 -> 2.8840234e+08 | H57: =SUM($D$8:$D$47)*$B$3 -> 2.8840234e+08 | I57: =SUM($D$8:$D$47)*$B$3 -> 2.8840234e+08
A58: Efecto cambiario sobre intereses | B58: =SUMPRODUCT($D$8:$D$47,'Trayectorias TRM'!C$6:C$45-$B$3) -> 0 | C58: =SUMPRODUCT($D$8:$D$47,'Trayectorias TRM'!D$6:D$45-$B$3) -> 34499793 | D58: =SUMPRODUCT($D$8:$D$47,'Trayectorias TRM'!E$6:E$45-$B$3) -> 11849470 | E58: =SUMPRODUCT($D$8:$D$47,'Trayectorias TRM'!F$6:F$45-$B$3) -> 63583567 | F58: =SUMPRODUCT($D$8:$D$47,'Trayectorias TRM'!G$6:G$45-$B$3) -> -58191284 | G58: =SUMPRODUCT($D$8:$D$47,'Trayectorias TRM'!I$6:I$45-$B$3) -> 35383118 | H58: =SUMPRODUCT($D$8:$D$47,'Trayectorias TRM'!K$6:K$45-$B$3) -> 1.8176366e+08 | I58: =SUMPRODUCT($D$8:$D$47,'Trayectorias TRM'!L$6:L$45-$B$3) -> 45127940
A59: Efecto cambiario sobre capital | B59: =SUMPRODUCT($E$8:$E$47,'Trayectorias TRM'!C$6:C$45-$B$3) -> 0 | C59: =SUMPRODUCT($E$8:$E$47,'Trayectorias TRM'!D$6:D$45-$B$3) -> 62098159 | D59: =SUMPRODUCT($E$8:$E$47,'Trayectorias TRM'!E$6:E$45-$B$3) -> 31304444 | E59: =SUMPRODUCT($E$8:$E$47,'Trayectorias TRM'!F$6:F$45-$B$3) -> 1.0169544e+08 | F59: =SUMPRODUCT($E$8:$E$47,'Trayectorias TRM'!G$6:G$45-$B$3) -> -96856746 | G59: =SUMPRODUCT($E$8:$E$47,'Trayectorias TRM'!I$6:I$45-$B$3) -> 63326250 | H59: =SUMPRODUCT($E$8:$E$47,'Trayectorias TRM'!K$6:K$45-$B$3) -> 3.3913127e+08 | I59: =SUMPRODUCT($E$8:$E$47,'Trayectorias TRM'!L$6:L$45-$B$3) -> 84740258
A60: Comprobación (suma − total) | B60: =ROUND(SUM(B56:B59)-B53,0) -> 0 | C60: =ROUND(SUM(C56:C59)-C53,0) -> 0 | D60: =ROUND(SUM(D56:D59)-D53,0) -> 0 | E60: =ROUND(SUM(E56:E59)-E53,0) -> 0 | F60: =ROUND(SUM(F56:F59)-F53,0) -> 0 | G60: =ROUND(SUM(G56:G59)-G53,0) -> 0 | H60: =ROUND(SUM(H56:H59)-H53,0) -> 0 | I60: =ROUND(SUM(I56:I59)-I53,0) -> 0
A61: Cuota máxima (COP) | B61: =MAX(F8:F47) -> 16210058 | C61: =MAX(G8:G47) -> 20428258 | D61: =MAX(H8:H47) -> 18912892 | E61: =MAX(I8:I47) -> 22378035 | F61: =MAX(J8:J47) -> 15515505 | G61: =MAX(K8:K47) -> 20511832 | H61: =MAX(L8:L47) -> 39723545 | I61: =MAX(M8:M47) -> 22197403
A62: Costo efectivo anual en COP (TIR) | B62: =(1+IRR(B68:B108))^4-1 -> 0.13647593 | C62: =(1+IRR(C68:C108))^4-1 -> 0.16939587 | D62: =(1+IRR(D68:D108))^4-1 -> 0.14891638 | E62: =(1+IRR(E68:E108))^4-1 -> 0.19485355 | F62: =(1+IRR(F68:F108))^4-1 -> 0.072495105 | G62: =(1+IRR(G68:G108))^4-1 -> 0.17017612 | H62: =(1+IRR(H68:H108))^4-1 -> 0.28062054 | I62: =(1+IRR(I68:I108))^4-1 -> 0.17894916
A63: Promedio de la TRM durante el crédito | B63: =AVERAGE('Trayectorias TRM'!C$6:C$45) -> 3174.67 | C63: =AVERAGE('Trayectorias TRM'!D$6:D$45) -> 3647.6273 | D63: =AVERAGE('Trayectorias TRM'!E$6:E$45) -> 3385.9577 | E63: =AVERAGE('Trayectorias TRM'!F$6:F$45) -> 3983.8995 | F63: =AVERAGE('Trayectorias TRM'!G$6:G$45) -> 2415.5328 | G63: =AVERAGE('Trayectorias TRM'!I$6:I$45) -> 3657.9651 | H63: =AVERAGE('Trayectorias TRM'!K$6:K$45) -> 5725.0456 | I63: =AVERAGE('Trayectorias TRM'!L$6:L$45) -> 3810.5232
A66: Flujos en COP para calcular la TIR (trimestre 0 = desembolso recibido)
A67: Trimestre | B67: TRM spot | C67: Escenario base | D67: Peso fuerte | E67: Peso débil | F67: Simulación P5 | G67: Simulación P50 | H67: Simulación P95 | I67: Simulación media
A68: 0 | B68: =$B$5 -> 360000000 | C68: =$B$5 -> 360000000 | D68: =$B$5 -> 360000000 | E68: =$B$5 -> 360000000 | F68: =$B$5 -> 360000000 | G68: =$B$5 -> 360000000 | H68: =$B$5 -> 360000000 | I68: =$B$5 -> 360000000
A69: 1 | B69: =-F8 -> -16210058 | C69: =-G8 -> -16457121 | D69: =-H8 -> -16143047 | E69: =-I8 -> -16836488 | F69: =-J8 -> -15272255 | G69: =-K8 -> -16477735 | H69: =-L8 -> -17784897 | I69: =-M8 -> -16497255
A70: 2 | B70: =-F9 -> -16210058 | C70: =-G9 -> -16707949 | D70: =-H9 -> -16076313 | E70: =-I9 -> -17487126 | F70: =-J9 -> -15150281 | G70: =-K9 -> -16736022 | H70: =-L9 -> -18525210 | I70: =-M9 -> -16774908
A71: 3 | B71: =-F10 -> -16210058 | C71: =-G10 -> -16962600 | D71: =-H10 -> -16009854 | E71: =-I10 -> -18162908 | F71: =-J10 -> -15259964 | G71: =-K10 -> -16977448 | H71: =-L10 -> -19069517 | I71: =-M10 -> -17047665
...

Sheet B Supuestos
A1: Parte B – Supuestos de la cobertura y coherencia del nominal
A2: Celdas amarillas = parámetros que se pueden cambiar (todo el análisis de las hojas B.2 y B.3 con fórmulas se recalcula).
A3: Parámetro | B3: Valor | C3: Fuente / cálculo
A4: Porcentaje de la exposición cubierto | B4: 0.75
A5: Trimestre en que se inicia la cobertura (fin del año 6) | B5: 24
A6: Cuota trimestral (USD) | B6: =Supuestos!B18 -> 5106.0609 | C6: Hoja Supuestos
A7: Cuotas pendientes al fin del año 6 | B7: =Supuestos!B12-B5 -> 16 | C7: 40 − 24
A8: Exposición pendiente (USD) | B8: =B6*B7 -> 81696.975 | C8: Pagos programados de los años 7 a 10
A9: Total a cubrir (USD) | B9: =B4*B8 -> 61272.731 | C9: 75 % de la exposición pendiente
A10: i_COP para pactar los forwards (EA) | B10: ='B.1 Forward'!B35 -> 0.12949826 | C10: Tasa implícita en el forward de mercado (hoja B.1)
A11: i_USD para pactar los forwards (EA) | B11: ='B.1 Forward'!B25 -> 0.0447 | C11: Tesoro de EE. UU. a 1 año (hoja B.1)
A12: Prima forward anual | B12: =(1+B10)/(1+B11)-1 -> 0.081169961 | C12: (1 + i_COP) / (1 + i_USD) − 1
A13: Tasa de descuento en pesos para el VPN (EA) | B13: 0.13 | C13: TES a 10 años por encima de 13 % (La República, 21/10/2026)
A14: Tasa de descuento trimestral | B14: =(1+B13)^(1/4)-1 -> 0.031025985 | C14: Cálculo
A15: Tolerancia presupuestal | B15: 0.1 | C15: «Fracaso de la cobertura»: costo cubierto del año > presupuesto al forward + 10 %
A16: Umbral de pérdida cambiaria extrema | B16: 0.2 | C16: Depreciación > 20 % en el año del forward (como 2002, 2008-09, 2014-15, 2020 y 2022)
A18: Forwards y coherencia entre nominal cubierto y obligación real
A19: Forward | B19: Año que cubre | C19: Trimestre de pacto | D19: Trimestre de vencimiento | E19: Pagos USD del año | F19: Nominal (USD) | G19: ¿Nominal ≤ pagos del año? | H19: Obligación pendiente al pactar (USD) | I19: Nominal vigente + por pactar (USD) | J19: ¿Cubierto ≤ obligación? | K19: Saldo de capital al pactar (USD)
A20: 1 | B20: 7 | C20: =$B$5+4*(A20-1) -> 24 | D20: =C20+4 -> 28 | E20: =SUMIF(Amortización!$B$5:$B$44,B20,Amortización!$D$5:$D$44) -> 20424.244 | F20: =$B$4*E20 -> 15318.183 | G20: =IF(F20<=E20+0.005,"Sí","No") -> Sí | H20: =SUMIF(Amortización!$A$5:$A$44,">"&C20,Amortización!$D$5:$D$44) -> 81696.975 | I20: =SUM(F20:$F$23) -> 61272.731 | J20: =IF(I20<=H20+0.005,"Sí","No") -> Sí | K20: =INDEX(Amortización!$G$5:$G$44,C20) -> 62928.921
A21: 2 | B21: 8 | C21: =$B$5+4*(A21-1) -> 28 | D21: =C21+4 -> 32 | E21: =SUMIF(Amortización!$B$5:$B$44,B21,Amortización!$D$5:$D$44) -> 20424.244 | F21: =$B$4*E21 -> 15318.183 | G21: =IF(F21<=E21+0.005,"Sí","No") -> Sí | H21: =SUMIF(Amortización!$A$5:$A$44,">"&C21,Amortización!$D$5:$D$44) -> 61272.731 | I21: =SUM(F21:$F$23) -> 45954.548 | J21: =IF(I21<=H21+0.005,"Sí","No") -> Sí | K21: =INDEX(Amortización!$G$5:$G$44,C21) -> 50075.529
A22: 3 | B22: 9 | C22: =$B$5+4*(A22-1) -> 32 | D22: =C22+4 -> 36 | E22: =SUMIF(Amortización!$B$5:$B$44,B22,Amortización!$D$5:$D$44) -> 20424.244 | F22: =$B$4*E22 -> 15318.183 | G22: =IF(F22<=E22+0.005,"Sí","No") -> Sí | H22: =SUMIF(Amortización!$A$5:$A$44,">"&C22,Amortización!$D$5:$D$44) -> 40848.487 | I22: =SUM(F22:$F$23) -> 30636.366 | J22: =IF(I22<=H22+0.005,"Sí","No") -> Sí | K22: =INDEX(Amortización!$G$5:$G$44,C22) -> 35467.96
A23: 4 | B23: 10 | C23: =$B$5+4*(A23-1) -> 36 | D23: =C23+4 -> 40 | E23: =SUMIF(Amortización!$B$5:$B$44,B23,Amortización!$D$5:$D$44) -> 20424.244 | F23: =$B$4*E23 -> 15318.183 | G23: =IF(F23<=E23+0.005,"Sí","No") -> Sí | H23: =SUMIF(Amortización!$A$5:$A$44,">"&C23,Amortización!$D$5:$D$44) -> 20424.244 | I23: =SUM(F23:$F$23) -> 15318.183 | J23: =IF(I23<=H23+0.005,"Sí","No") -> Sí | K23: =INDEX(Amortización!$G$5:$G$44,C23) -> 18866.809
A24: Total | E24: =SUM(E20:E23) -> 81696.975 | F24: =SUM(F20:F23) -> 61272.731
A25: Comprobación: total nominal = total a cubrir | F25: =IF(ABS(F24-B9)<0.01,"Correcto","Revisar") -> Correcto

Sheet B.1 Forward
A1: B.1 Cotización y valoración del forward USD/COP
A2: Valores en azul = datos consultados (con fuente); las demás cifras son fórmulas. La cotización de SET-FX para forwards no es de acceso público; se usa la curva forward USD/COP de Cbonds (precio medio al cierre de Londres) y se verifica con la TRM oficial y el cierre de SET-FX.
A4: Dato | B4: Valor (COP por USD) | C4: Fuente | D4: Fecha del dato | E4: Fecha de consulta | F4: Nota
A5: Spot (S/N) | B5: 3132.07 | C5: Cbonds, USD/COP S/N FX Forward Rate (Mid), https://cbonds.com.tr/indexes/215883/ | D5: 46322 | E5: 46323 | F5: Spot de referencia para los puntos forward
A6: Forward 6 meses | B6: 3252.9 | C6: Cbonds, misma página (tenor 6M) | D6: 46322 | E6: 46323 | F6: Plazo superior a seis meses
A7: Forward 1 año | B7: 3386.3 | C7: Cbonds, USD/COP 1Y FX Forward Rate (Mid), https://cbonds.com/indexes/215895/ | D7: 46322 | E7: 46323 | F7: Plazo de cada forward de la estrategia
A8: Forward 2 años | B8: 3654.14 | C8: Cbonds, misma página (tenor 2Y) | D8: 46322 | E8: 46323 | F8: Referencia de la pendiente de la curva
A9: TRM vigente | B9: 3148.02 | C9: Banco de la República, https://totoro.banrep.gov.co/estadisticas-economicas/ | D9: 46323 | E9: 46323 | F9: Tasa oficial (promedio del día hábil anterior)
A10: Cierre promedio SET-FX | B10: 3157.57 | C10: Infobae con datos de SET-FX, https://www.infobae.com/colombia/2026/10/26/dolar-hoy-en-colombia-cotizacion-de-cierre-del-26-de-octubre/ | D10: 46321 | E10: 46323 | F10: Mercado spot interbancario colombiano
A12: Puntos forward y devaluación implícita
A13: Plazo | B13: Años | C13: Forward | D13: Puntos forward (COP) | E13: Devaluación implícita del plazo | F13: Devaluación implícita anual
A14: 6 meses | B14: 0.5 | C14: =B6 -> 3252.9 | D14: =C14-$B$5 -> 120.83 | E14: =C14/$B$5-1 -> 0.03857832 | F14: =(1+E14)^(1/B14)-1 -> 0.078644928
A15: 1 año | B15: 1 | C15: =B7 -> 3386.3 | D15: =C15-$B$5 -> 254.23 | E15: =C15/$B$5-1 -> 0.081169961 | F15: =(1+E15)^(1/B15)-1 -> 0.081169961
A16: 2 años | B16: 2 | C16: =B8 -> 3654.14 | D16: =C16-$B$5 -> 522.07 | E16: =C16/$B$5-1 -> 0.16668529 | F16: =(1+E16)^(1/B16)-1 -> 0.080132071
A18: Tasas de interés de referencia
A19: Tasa | B19: Valor | C19: Fuente | D19: Fecha del dato | E19: Plazo | F19: Convención
A20: Tasa de política del Banco de la República | B20: 0.1225 | C20: https://totoro.banrep.gov.co/estadisticas-economicas/ | D20: 46323 | E20: Un día | F20: Efectiva anual
A21: Tasa esperada del Banco de la República a fin de 2026 (encuesta) | B21: 0.125 | C21: Fedesarrollo-BVC, Encuesta de Opinión Financiera vía Portafolio, https://www.portafolio.co/economia/gobierno/una-inflacion-de-6-87-elevaria-las-tasas-del-banco-de-la-republica-a-12-50-al-cierre-de-2026-advierte-estudio-504862 | D21: 46316 | E21: Hasta dic. 2026 | F21: Efectiva anual
A22: TES a 1 año (TCO, subasta) | B22: 0.1348 | C22: La República, https://www.larepublica.co/economia/las-tasas-de-los-bonos-tes-de-corto-plazo-alcanzaron-maximos-de-mas-de-dos-decadas-4394066 | D22: 46154 | E22: 1 año | F22: Efectiva anual (dato de mayo: desactualizado)
A23: IBR a 1 mes | B23: 0.1156 | C23: Banco de Bogotá Internacional, https://www.bancodebogotainternacional.com/bbi/es/economicindicator | D23: 46322 | E23: 1 mes | F23: Nominal anual
A24: Fed funds efectiva | B24: 0.0388 | C24: Fed H.15, https://www.federalreserve.gov/releases/h15/ | D24: 46321 | E24: Un día | F24: Actual/360
A25: Tesoro de EE. UU. a 1 año (constant maturity) | B25: 0.0447 | C25: Fed H.15, https://www.federalreserve.gov/releases/h15/ | D25: 46321 | E25: 1 año | F25: Rendimiento equivalente de bono (semestral)
A27: Forward teórico a 1 año por paridad cubierta de tasas: F = S × (1 + i_COP) / (1 + i_USD)
A28: Combinación de tasas | B28: i_COP | C28: i_USD | D28: Forward teórico | E28: Forward observado | F28: Diferencia (COP) | G28: Diferencia (%) | H28: Lectura
A29: (a) Política BanRep vs Tesoro 1 año (base) | B29: =B20 -> 0.1225 | C29: =B25 -> 0.0447 | D29: =$B$5*(1+B29)/(1+C29) -> 3365.3188 | E29: =$B$7 -> 3386.3 | F29: =E29-D29 -> 20.981176 | G29: =E29/D29-1 -> 0.0062345286 | H29: Tasas usadas en A.1; i_COP es a un día
A30: (b) Tasa BanRep esperada vs Tesoro 1 año | B30: =B21 -> 0.125 | C30: =B25 -> 0.0447 | D30: =$B$5*(1+B30)/(1+C30) -> 3372.814 | E30: =$B$7 -> 3386.3 | F30: =E30-D30 -> 13.486034 | G30: =E30/D30-1 -> 0.0039984519 | H30: Incorpora la subida esperada para octubre
A31: (c) TES 1 año vs Tesoro 1 año | B31: =B22 -> 0.1348 | C31: =B25 -> 0.0447 | D31: =$B$5*(1+B31)/(1+C31) -> 3402.1949 | E31: =$B$7 -> 3386.3 | F31: =E31-D31 -> -15.894923 | G31: =E31/D31-1 -> -0.0046719613 | H31: Mismo plazo, pero incluye riesgo soberano y el dato es de mayo
A32: (d) Política BanRep vs fed funds | B32: =B20 -> 0.1225 | C32: =B24 -> 0.0388 | D32: =$B$5*(1+B32)/(1+C32) -> 3384.4326 | E32: =$B$7 -> 3386.3 | F32: =E32-D32 -> 1.8674095 | G32: =E32/D32-1 -> 0.00055176443 | H32: Plazos de un día: no corresponde a un forward de 1 año
A33: (e) Igual que (a), Tesoro convertido a efectiva anual | B33: =B20 -> 0.1225 | C33: =(1+B25/2)^2-1 -> 0.045199523 | D33: =$B$5*(1+B33)/(1+C33) -> 3363.7105 | E33: =$B$7 -> 3386.3 | F33: =E33-D33 -> 22.589532 | G33: =E33/D33-1 -> 0.0067156589 | H33: Efecto de la convención de capitalización
A35: Tasa en pesos implícita en el forward observado (con Tesoro 1 año) | B35: =$B$7/$B$5*(1+B25)-1 -> 0.12949826
A36: Diferencia frente a la tasa de política (pb) | B36: =(B35-B20)*10000 -> 69.982583

Sheet B.2 Escenarios
A1: B.2 Escenarios de protección y costo de oportunidad
A2: Parte 1 (fórmulas): para cada escenario de la hoja «Trayectorias B» se compara el forward pactado con la TRM al vencimiento. Parte 2 (valores de la simulación de 20.000 caminos): proporciones bajo innovaciones normales y t de Student.
A4: Escenario | B4: Forward | C4: Año | D4: TRM al pactar | E4: Forward pactado | F4: TRM al vencimiento | G4: Spot − forward (COP/USD) | H4: Resultado del forward | I4: Liquidación NDF (COP) | J4: Costo del año sin cobertura (COP) | K4: Costo combinado: 75 % cubierto + 25 % abierto (COP) | L4: Presupuesto al forward (COP) | M4: Desviación vs presupuesto sin cobertura | N4: Desviación vs presupuesto con cobertura | O4: Precio efectivo por USD con cobertura
A5: Favorable – Normal | B5: 1 | C5: 7 | D5: =INDEX('Trayectorias B'!$C$5:$I$45,'B Supuestos'!$C$20+1,1) -> 3826.6551 | E5: =D5*(1+'B Supuestos'!$B$12) -> 4137.2646 | F5: =INDEX('Trayectorias B'!$C$5:$I$45,'B Supuestos'!$D$20+1,1) -> 3005.8223 | G5: =F5-E5 -> -1131.4422 | H5: =IF(G5>0,"Protección","Costo de oportunidad") -> Costo de oportunidad | I5: ='B Supuestos'!$F$20*G5 -> -17331639 | J5: ='B Supuestos'!$B$6*SUM(INDEX('Trayectorias B'!$C$5:$I$45,'B Supuestos'!$C$20+2,1):INDEX('Trayectorias B'!$C$5:$I$45,'B Supuestos'!$D$20+1,1)) -> 72122755 | K5: =J5-I5 -> 89454394 | L5: =4*'B Supuestos'!$B$6*E5 -> 84500499 | M5: =J5/L5-1 -> -0.14648131 | N5: =K5/L5-1 -> 0.058625622 | O5: =K5/(4*'B Supuestos'!$B$6) -> 4379.8143
A6: Favorable – Normal | B6: 2 | C6: 8 | D6: =INDEX('Trayectorias B'!$C$5:$I$45,'B Supuestos'!$C$21+1,1) -> 3005.8223 | E6: =D6*(1+'B Supuestos'!$B$12) -> 3249.8048 | F6: =INDEX('Trayectorias B'!$C$5:$I$45,'B Supuestos'!$D$21+1,1) -> 3041.5009 | G6: =F6-E6 -> -208.30393 | H6: =IF(G6>0,"Protección","Costo de oportunidad") -> Costo de oportunidad | I6: ='B Supuestos'!$F$21*G6 -> -3190837.6 | J6: ='B Supuestos'!$B$6*SUM(INDEX('Trayectorias B'!$C$5:$I$45,'B Supuestos'!$C$21+2,1):INDEX('Trayectorias B'!$C$5:$I$45,'B Supuestos'!$D$21+1,1)) -> 62865873 | K6: =J6-I6 -> 66056711 | L6: =4*'B Supuestos'!$B$6*E6 -> 66374806 | M6: =J6/L6-1 -> -0.052865425 | N6: =K6/L6-1 -> -0.0047924011 | O6: =K6/(4*'B Supuestos'!$B$6) -> 3234.2305
A7: Favorable – Normal | B7: 3 | C7: 9 | D7: =INDEX('Trayectorias B'!$C$5:$I$45,'B Supuestos'!$C$22+1,1) -> 3041.5009 | E7: =D7*(1+'B Supuestos'!$B$12) -> 3288.3794 | F7: =INDEX('Trayectorias B'!$C$5:$I$45,'B Supuestos'!$D$22+1,1) -> 3249.0582 | G7: =F7-E7 -> -39.321225 | H7: =IF(G7>0,"Protección","Costo de oportunidad") -> Costo de oportunidad | I7: ='B Supuestos'!$F$22*G7 -> -602329.71 | J7: ='B Supuestos'!$B$6*SUM(INDEX('Trayectorias B'!$C$5:$I$45,'B Supuestos'!$C$22+2,1):INDEX('Trayectorias B'!$C$5:$I$45,'B Supuestos'!$D$22+1,1)) -> 66938316 | K7: =J7-I7 -> 67540646 | L7: =4*'B Supuestos'!$B$6*E7 -> 67162662 | M7: =J7/L7-1 -> -0.003340339 | N7: =K7/L7-1 -> 0.0056278836 | O7: =K7/(4*'B Supuestos'!$B$6) -> 3306.886
A8: Favorable – Normal | B8: 4 | C8: 10 | D8: =INDEX('Trayectorias B'!$C$5:$I$45,'B Supuestos'!$C$23+1,1) -> 3249.0582 | E8: =D8*(1+'B Supuestos'!$B$12) -> 3512.7841 | F8: =INDEX('Trayectorias B'!$C$5:$I$45,'B Supuestos'!$D$23+1,1) -> 2915.2257 | G8: =F8-E8 -> -597.55843 | H8: =IF(G8>0,"Protección","Costo de oportunidad") -> Costo de oportunidad | I8: ='B Supuestos'!$F$23*G8 -> -9153509.2 | J8: ='B Supuestos'!$B$6*SUM(INDEX('Trayectorias B'!$C$5:$I$45,'B Supuestos'!$C$23+2,1):INDEX('Trayectorias B'!$C$5:$I$45,'B Supuestos'!$D$23+1,1)) -> 63576219 | K8: =J8-I8 -> 72729728 | L8: =4*'B Supuestos'!$B$6*E8 -> 71745959 | M8: =J8/L8-1 -> -0.11387039 | N8: =K8/L8-1 -> 0.013711839 | O8: =K8/(4*'B Supuestos'!$B$6) -> 3560.9508
A9: Central – Normal | B9: 1 | C9: 7 | D9: =INDEX('Trayectorias B'!$C$5:$I$45,'B Supuestos'!$C$20+1,2) -> 3695.2578 | E9: =D9*(1+'B Supuestos'!$B$12) -> 3995.2017 | F9: =INDEX('Trayectorias B'!$C$5:$I$45,'B Supuestos'!$D$20+1,2) -> 3721.6324 | G9: =F9-E9 -> -273.56932 | H9: =IF(G9>0,"Protección","Costo de oportunidad") -> Costo de oportunidad | I9: ='B Supuestos'!$F$20*G9 -> -4190584.9 | J9: ='B Supuestos'!$B$6*SUM(INDEX('Trayectorias B'!$C$5:$I$45,'B Supuestos'!$C$20+2,2):INDEX('Trayectorias B'!$C$5:$I$45,'B Supuestos'!$D$20+1,2)) -> 73789513 | K9: =J9-I9 -> 77980098 | L9: =4*'B Supuestos'!$B$6*E9 -> 81598973 | M9: =J9/L9-1 -> -0.095705369 | N9: =K9/L9-1 -> -0.044349515 | O9: =K9/(4*'B Supuestos'!$B$6) -> 3818.0164
A10: Central – Normal | B10: 2 | C10: 8 | D10: =INDEX('Trayectorias B'!$C$5:$I$45,'B Supuestos'!$C$21+1,2) -> 3721.6324 | E10: =D10*(1+'B Supuestos'!$B$12) -> 4023.7171 | F10: =INDEX('Trayectorias B'!$C$5:$I$45,'B Supuestos'!$D$21+1,2) -> 3336.8079 | G10: =F10-E10 -> -686.90924 | H10: =IF(G10>0,"Protección","Costo de oportunidad") -> Costo de oportunidad | I10: ='B Supuestos'!$F$21*G10 -> -10522201 | J10: ='B Supuestos'!$B$6*SUM(INDEX('Trayectorias B'!$C$5:$I$45,'B Supuestos'!$C$21+2,2):INDEX('Trayectorias B'!$C$5:$I$45,'B Supuestos'!$D$21+1,2)) -> 74197868 | K10: =J10-I10 -> 84720070 | L10: =4*'B Supuestos'!$B$6*E10 -> 82181379 | M10: =J10/L10-1 -> -0.097145005 | N10: =K10/L10-1 -> 0.030891314 | O10: =K10/(4*'B Supuestos'!$B$6) -> 4148.015
A11: Central – Normal | B11: 3 | C11: 9 | D11: =INDEX('Trayectorias B'!$C$5:$I$45,'B Supuestos'!$C$22+1,2) -> 3336.8079 | E11: =D11*(1+'B Supuestos'!$B$12) -> 3607.6564 | F11: =INDEX('Trayectorias B'!$C$5:$I$45,'B Supuestos'!$D$22+1,2) -> 3548.8586 | G11: =F11-E11 -> -58.797842 | H11: =IF(G11>0,"Protección","Costo de oportunidad") -> Costo de oportunidad | I11: ='B Supuestos'!$F$22*G11 -> -900676.09 | J11: ='B Supuestos'!$B$6*SUM(INDEX('Trayectorias B'!$C$5:$I$45,'B Supuestos'!$C$22+2,2):INDEX('Trayectorias B'!$C$5:$I$45,'B Supuestos'!$D$22+1,2)) -> 68742292 | K11: =J11-I11 -> 69642968 | L11: =4*'B Supuestos'!$B$6*E11 -> 73683654 | M11: =J11/L11-1 -> -0.06706185 | N11: =K11/L11-1 -> -0.054838296 | O11: =K11/(4*'B Supuestos'!$B$6) -> 3409.8187
A12: Central – Normal | B12: 4 | C12: 10 | D12: =INDEX('Trayectorias B'!$C$5:$I$45,'B Supuestos'!$C$23+1,2) -> 3548.8586 | E12: =D12*(1+'B Supuestos'!$B$12) -> 3836.9193 | F12: =INDEX('Trayectorias B'!$C$5:$I$45,'B Supuestos'!$D$23+1,2) -> 3994.0644 | G12: =F12-E12 -> 157.14514 | H12: =IF(G12>0,"Protección","Costo de oportunidad") -> Protección | I12: ='B Supuestos'!$F$23*G12 -> 2407177.9 | J12: ='B Supuestos'!$B$6*SUM(INDEX('Trayectorias B'!$C$5:$I$45,'B Supuestos'!$C$23+2,2):INDEX('Trayectorias B'!$C$5:$I$45,'B Supuestos'!$D$23+1,2)) -> 78835204 | K12: =J12-I12 -> 76428026 | L12: =4*'B Supuestos'!$B$6*E12 -> 78366175 | M12: =J12/L12-1 -> 0.0059850963 | N12: =K12/L12-1 -> -0.024731956 | O12: =K12/(4*'B Supuestos'!$B$6) -> 3742.0248
A13: Adverso – Normal | B13: 1 | C13: 7 | D13: =INDEX('Trayectorias B'!$C$5:$I$45,'B Supuestos'!$C$20+1,3) -> 3823.1388 | E13: =D13*(1+'B Supuestos'!$B$12) -> 4133.4629 | F13: =INDEX('Trayectorias B'!$C$5:$I$45,'B Supuestos'!$D$20+1,3) -> 4709.8614 | G13: =F13-E13 -> 576.39853 | H13: =IF(G13>0,"Protección","Costo de oportunidad") -> Protección | I13: ='B Supuestos'!$F$20*G13 -> 8829378 | J13: ='B Supuestos'!$B$6*SUM(INDEX('Trayectorias B'!$C$5:$I$45,'B Supuestos'!$C$20+2,3):INDEX('Trayectorias B'!$C$5:$I$45,'B Supuestos'!$D$20+1,3)) -> 87962724 | K13: =J13-I13 -> 79133346 | L13: =4*'B Supuestos'!$B$6*E13 -> 84422853 | M13: =J13/L13-1 -> 0.041930245 | N13: =K13/L13-1 -> -0.06265492 | O13: =K13/(4*'B Supuestos'!$B$6) -> 3874.4811
A14: Adverso – Normal | B14: 2 | C14: 8 | D14: =INDEX('Trayectorias B'!$C$5:$I$45,'B Supuestos'!$C$21+1,3) -> 4709.8614 | E14: =D14*(1+'B Supuestos'!$B$12) -> 5092.1607 | F14: =INDEX('Trayectorias B'!$C$5:$I$45,'B Supuestos'!$D$21+1,3) -> 5059.3468 | G14: =F14-E14 -> -32.813908 | H14: =IF(G14>0,"Protección","Costo de oportunidad") -> Costo de oportunidad | I14: ='B Supuestos'!$F$21*G14 -> -502649.44 | J14: ='B Supuestos'!$B$6*SUM(INDEX('Trayectorias B'!$C$5:$I$45,'B Supuestos'!$C$21+2,3):INDEX('Trayectorias B'!$C$5:$I$45,'B Supuestos'!$D$21+1,3)) -> 96891375 | K14: =J14-I14 -> 97394025 | L14: =4*'B Supuestos'!$B$6*E14 -> 1.0400353e+08 | M14: =J14/L14-1 -> -0.068383783 | N14: =K14/L14-1 -> -0.063550779 | O14: =K14/(4*'B Supuestos'!$B$6) -> 4768.5499
A15: Adverso – Normal | B15: 3 | C15: 9 | D15: =INDEX('Trayectorias B'!$C$5:$I$45,'B Supuestos'!$C$22+1,3) -> 5059.3468 | E15: =D15*(1+'B Supuestos'!$B$12) -> 5470.0137 | F15: =INDEX('Trayectorias B'!$C$5:$I$45,'B Supuestos'!$D$22+1,3) -> 5425.4503 | G15: =F15-E15 -> -44.56346 | H15: =IF(G15>0,"Protección","Costo de oportunidad") -> Costo de oportunidad | I15: ='B Supuestos'!$F$22*G15 -> -682631.23 | J15: ='B Supuestos'!$B$6*SUM(INDEX('Trayectorias B'!$C$5:$I$45,'B Supuestos'!$C$22+2,3):INDEX('Trayectorias B'!$C$5:$I$45,'B Supuestos'!$D$22+1,3)) -> 1.0206275e+08 | K15: =J15-I15 -> 1.0274538e+08 | L15: =4*'B Supuestos'!$B$6*E15 -> 1.1172089e+08 | M15: =J15/L15-1 -> -0.086448899 | N15: =K15/L15-1 -> -0.080338751 | O15: =K15/(4*'B Supuestos'!$B$6) -> 5030.5597
A16: Adverso – Normal | B16: 4 | C16: 10 | D16: =INDEX('Trayectorias B'!$C$5:$I$45,'B Supuestos'!$C$23+1,3) -> 5425.4503 | E16: =D16*(1+'B Supuestos'!$B$12) -> 5865.8339 | F16: =INDEX('Trayectorias B'!$C$5:$I$45,'B Supuestos'!$D$23+1,3) -> 5759.8568 | G16: =F16-E16 -> -105.97703 | H16: =IF(G16>0,"Protección","Costo de oportunidad") -> Costo de oportunidad | I16: ='B Supuestos'!$F$23*G16 -> -1623375.6 | J16: ='B Supuestos'!$B$6*SUM(INDEX('Trayectorias B'!$C$5:$I$45,'B Supuestos'!$C$23+2,3):INDEX('Trayectorias B'!$C$5:$I$45,'B Supuestos'!$D$23+1,3)) -> 1.1484962e+08 | K16: =J16-I16 -> 1.16473e+08 | L16: =4*'B Supuestos'!$B$6*E16 -> 1.1980522e+08 | M16: =J16/L16-1 -> -0.041363771 | N16: =K16/L16-1 -> -0.027813647 | O16: =K16/(4*'B Supuestos'!$B$6) -> 5702.6836
A17: Favorable – t | B17: 1 | C17: 7 | D17: =INDEX('Trayectorias B'!$C$5:$I$45,'B Supuestos'!$C$20+1,4) -> 3590.8697 | E17: =D17*(1+'B Supuestos'!$B$12) -> 3882.3404 | F17: =INDEX('Trayectorias B'!$C$5:$I$45,'B Supuestos'!$D$20+1,4) -> 3219.7964 | G17: =F17-E17 -> -662.54404 | H17: =IF(G17>0,"Protección","Costo de oportunidad") -> Costo de oportunidad | I17: ='B Supuestos'!$F$20*G17 -> -10148971 | J17: ='B Supuestos'!$B$6*SUM(INDEX('Trayectorias B'!$C$5:$I$45,'B Supuestos'!$C$20+2,4):INDEX('Trayectorias B'!$C$5:$I$45,'B Supuestos'!$D$20+1,4)) -> 70125882 | K17: =J17-I17 -> 80274853 | L17: =4*'B Supuestos'!$B$6*E17 -> 79293866 | M17: =J17/L17-1 -> -0.11562035 | N17: =K17/L17-1 -> 0.012371527 | O17: =K17/(4*'B Supuestos'!$B$6) -> 3930.3709
A18: Favorable – t | B18: 2 | C18: 8 | D18: =INDEX('Trayectorias B'!$C$5:$I$45,'B Supuestos'!$C$21+1,4) -> 3219.7964 | E18: =D18*(1+'B Supuestos'!$B$12) -> 3481.1471 | F18: =INDEX('Trayectorias B'!$C$5:$I$45,'B Supuestos'!$D$21+1,4) -> 2966.9503 | G18: =F18-E18 -> -514.19684 | H18: =IF(G18>0,"Protección","Costo de oportunidad") -> Costo de oportunidad | I18: ='B Supuestos'!$F$21*G18 -> -7876561.2 | J18: ='B Supuestos'!$B$6*SUM(INDEX('Trayectorias B'!$C$5:$I$45,'B Supuestos'!$C$21+2,4):INDEX('Trayectorias B'!$C$5:$I$45,'B Supuestos'!$D$21+1,4)) -> 64081734 | K18: =J18-I18 -> 71958295 | L18: =4*'B Supuestos'!$B$6*E18 -> 71099797 | M18: =J18/L18-1 -> -0.098707217 | N18: =K18/L18-1 -> 0.012074551 | O18: =K18/(4*'B Supuestos'!$B$6) -> 3523.1804
A19: Favorable – t | B19: 3 | C19: 9 | D19: =INDEX('Trayectorias B'!$C$5:$I$45,'B Supuestos'!$C$22+1,4) -> 2966.9503 | E19: =D19*(1+'B Supuestos'!$B$12) -> 3207.7775 | F19: =INDEX('Trayectorias B'!$C$5:$I$45,'B Supuestos'!$D$22+1,4) -> 3286.7372 | G19: =F19-E19 -> 78.959728 | H19: =IF(G19>0,"Protección","Costo de oportunidad") -> Protección | I19: ='B Supuestos'!$F$22*G19 -> 1209519.5 | J19: ='B Supuestos'!$B$6*SUM(INDEX('Trayectorias B'!$C$5:$I$45,'B Supuestos'!$C$22+2,4):INDEX('Trayectorias B'!$C$5:$I$45,'B Supuestos'!$D$22+1,4)) -> 65036998 | K19: =J19-I19 -> 63827479 | L19: =4*'B Supuestos'!$B$6*E19 -> 65516429 | M19: =J19/L19-1 -> -0.0073177267 | N19: =K19/L19-1 -> -0.025779043 | O19: =K19/(4*'B Supuestos'!$B$6) -> 3125.0841
A20: Favorable – t | B20: 4 | C20: 10 | D20: =INDEX('Trayectorias B'!$C$5:$I$45,'B Supuestos'!$C$23+1,4) -> 3286.7372 | E20: =D20*(1+'B Supuestos'!$B$12) -> 3553.5216 | F20: =INDEX('Trayectorias B'!$C$5:$I$45,'B Supuestos'!$D$23+1,4) -> 2741.3926 | G20: =F20-E20 -> -812.12893 | H20: =IF(G20>0,"Protección","Costo de oportunidad") -> Costo de oportunidad | I20: ='B Supuestos'!$F$23*G20 -> -12440339 | J20: ='B Supuestos'!$B$6*SUM(INDEX('Trayectorias B'!$C$5:$I$45,'B Supuestos'!$C$23+2,4):INDEX('Trayectorias B'!$C$5:$I$45,'B Supuestos'!$D$23+1,4)) -> 62925711 | K20: =J20-I20 -> 75366050 | L20: =4*'B Supuestos'!$B$6*E20 -> 72577990 | M20: =J20/L20-1 -> -0.13299183 | N20: =K20/L20-1 -> 0.038414673 | O20: =K20/(4*'B Supuestos'!$B$6) -> 3690.0289
A21: Central – t | B21: 1 | C21: 7 | D21: =INDEX('Trayectorias B'!$C$5:$I$45,'B Supuestos'!$C$20+1,5) -> 3784.6602 | E21: =D21*(1+'B Supuestos'!$B$12) -> 4091.8609 | F21: =INDEX('Trayectorias B'!$C$5:$I$45,'B Supuestos'!$D$20+1,5) -> 4345.86 | G21: =F21-E21 -> 253.99909 | H21: =IF(G21>0,"Protección","Costo de oportunidad") -> Protección | I21: ='B Supuestos'!$F$20*G21 -> 3890804.5 | J21: ='B Supuestos'!$B$6*SUM(INDEX('Trayectorias B'!$C$5:$I$45,'B Supuestos'!$C$20+2,5):INDEX('Trayectorias B'!$C$5:$I$45,'B Supuestos'!$D$20+1,5)) -> 85292505 | K21: =J21-I21 -> 81401701 | L21: =4*'B Supuestos'!$B$6*E21 -> 83573164 | M21: =J21/L21-1 -> 0.020572893 | N21: =K21/L21-1 -> -0.025982775 | O21: =K21/(4*'B Supuestos'!$B$6) -> 3985.543
A22: Central – t | B22: 2 | C22: 8 | D22: =INDEX('Trayectorias B'!$C$5:$I$45,'B Supuestos'!$C$21+1,5) -> 4345.86 | E22: =D22*(1+'B Supuestos'!$B$12) -> 4698.6132 | F22: =INDEX('Trayectorias B'!$C$5:$I$45,'B Supuestos'!$D$21+1,5) -> 4535.5778 | G22: =F22-E22 -> -163.0355 | H22: =IF(G22>0,"Protección","Costo de oportunidad") -> Costo de oportunidad | I22: ='B Supuestos'!$F$21*G22 -> -2497407.5 | J22: ='B Supuestos'!$B$6*SUM(INDEX('Trayectorias B'!$C$5:$I$45,'B Supuestos'!$C$21+2,5):INDEX('Trayectorias B'!$C$5:$I$45,'B Supuestos'!$D$21+1,5)) -> 94635838 | K22: =J22-I22 -> 97133246 | L22: =4*'B Supuestos'!$B$6*E22 -> 95965622 | M22: =J22/L22-1 -> -0.013856873 | N22: =K22/L22-1 -> 0.012167108 | O22: =K22/(4*'B Supuestos'!$B$6) -> 4755.7818
A23: Central – t | B23: 3 | C23: 9 | D23: =INDEX('Trayectorias B'!$C$5:$I$45,'B Supuestos'!$C$22+1,5) -> 4535.5778 | E23: =D23*(1+'B Supuestos'!$B$12) -> 4903.7304 | F23: =INDEX('Trayectorias B'!$C$5:$I$45,'B Supuestos'!$D$22+1,5) -> 4959.0442 | G23: =F23-E23 -> 55.313744 | H23: =IF(G23>0,"Protección","Costo de oportunidad") -> Protección | I23: ='B Supuestos'!$F$22*G23 -> 847306.03 | J23: ='B Supuestos'!$B$6*SUM(INDEX('Trayectorias B'!$C$5:$I$45,'B Supuestos'!$C$22+2,5):INDEX('Trayectorias B'!$C$5:$I$45,'B Supuestos'!$D$22+1,5)) -> 96674367 | K23: =J23-I23 -> 95827061 | L23: =4*'B Supuestos'!$B$6*E23 -> 1.0015499e+08 | M23: =J23/L23-1 -> -0.034752322 | N23: =K23/L23-1 -> -0.043212271 | O23: =K23/(4*'B Supuestos'!$B$6) -> 4691.8291
A24: Central – t | B24: 4 | C24: 10 | D24: =INDEX('Trayectorias B'!$C$5:$I$45,'B Supuestos'!$C$23+1,5) -> 4959.0442 | E24: =D24*(1+'B Supuestos'!$B$12) -> 5361.5696 | F24: =INDEX('Trayectorias B'!$C$5:$I$45,'B Supuestos'!$D$23+1,5) -> 4141.8056 | G24: =F24-E24 -> -1219.764 | H24: =IF(G24>0,"Protección","Costo de oportunidad") -> Costo de oportunidad | I24: ='B Supuestos'!$F$23*G24 -> -18684567 | J24: ='B Supuestos'!$B$6*SUM(INDEX('Trayectorias B'!$C$5:$I$45,'B Supuestos'!$C$23+2,5):INDEX('Trayectorias B'!$C$5:$I$45,'B Supuestos'!$D$23+1,5)) -> 84988567 | K24: =J24-I24 -> 1.0367313e+08 | L24: =4*'B Supuestos'!$B$6*E24 -> 1.09506e+08 | M24: =J24/L24-1 -> -0.22389125 | N24: =K24/L24-1 -> -0.053265292 | O24: =K24/(4*'B Supuestos'!$B$6) -> 5075.984
A25: Adverso – t | B25: 1 | C25: 7 | D25: =INDEX('Trayectorias B'!$C$5:$I$45,'B Supuestos'!$C$20+1,6) -> 3691.5684 | E25: =D25*(1+'B Supuestos'!$B$12) -> 3991.2129 | F25: =INDEX('Trayectorias B'!$C$5:$I$45,'B Supuestos'!$D$20+1,6) -> 3954.1369 | G25: =F25-E25 -> -37.076001 | H25: =IF(G25>0,"Protección","Costo de oportunidad") -> Costo de oportunidad | I25: ='B Supuestos'!$F$20*G25 -> -567936.96 | J25: ='B Supuestos'!$B$6*SUM(INDEX('Trayectorias B'!$C$5:$I$45,'B Supuestos'!$C$20+2,6):INDEX('Trayectorias B'!$C$5:$I$45,'B Supuestos'!$D$20+1,6)) -> 79033633 | K25: =J25-I25 -> 79601570 | L25: =4*'B Supuestos'!$B$6*E25 -> 81517504 | M25: =J25/L25-1 -> -0.030470401 | N25: =K25/L25-1 -> -0.023503345 | O25: =K25/(4*'B Supuestos'!$B$6) -> 3897.406
A26: Adverso – t | B26: 2 | C26: 8 | D26: =INDEX('Trayectorias B'!$C$5:$I$45,'B Supuestos'!$C$21+1,6) -> 3954.1369 | E26: =D26*(1+'B Supuestos'!$B$12) -> 4275.094 | F26: =INDEX('Trayectorias B'!$C$5:$I$45,'B Supuestos'!$D$21+1,6) -> 5356.5356 | G26: =F26-E26 -> 1081.4416 | H26: =IF(G26>0,"Protección","Costo de oportunidad") -> Protección | I26: ='B Supuestos'!$F$21*G26 -> 16565721 | J26: ='B Supuestos'!$B$6*SUM(INDEX('Trayectorias B'!$C$5:$I$45,'B Supuestos'!$C$21+2,6):INDEX('Trayectorias B'!$C$5:$I$45,'B Supuestos'!$D$21+1,6)) -> 1.0110693e+08 | K26: =J26-I26 -> 84541210 | L26: =4*'B Supuestos'!$B$6*E26 -> 87315561 | M26: =J26/L26-1 -> 0.15794859 | N26: =K26/L26-1 -> -0.031773843 | O26: =K26/(4*'B Supuestos'!$B$6) -> 4139.2578
A27: Adverso – t | B27: 3 | C27: 9 | D27: =INDEX('Trayectorias B'!$C$5:$I$45,'B Supuestos'!$C$22+1,6) -> 5356.5356 | E27: =D27*(1+'B Supuestos'!$B$12) -> 5791.3254 | F27: =INDEX('Trayectorias B'!$C$5:$I$45,'B Supuestos'!$D$22+1,6) -> 5423.644 | G27: =F27-E27 -> -367.68144 | H27: =IF(G27>0,"Protección","Costo de oportunidad") -> Costo de oportunidad | I27: ='B Supuestos'!$F$22*G27 -> -5632211.4 | J27: ='B Supuestos'!$B$6*SUM(INDEX('Trayectorias B'!$C$5:$I$45,'B Supuestos'!$C$22+2,6):INDEX('Trayectorias B'!$C$5:$I$45,'B Supuestos'!$D$22+1,6)) -> 1.0230832e+08 | K27: =J27-I27 -> 1.0794053e+08 | L27: =4*'B Supuestos'!$B$6*E27 -> 1.1828344e+08 | M27: =J27/L27-1 -> -0.13505797 | N27: =K27/L27-1 -> -0.087441739 | O27: =K27/(4*'B Supuestos'!$B$6) -> 5284.9218
A28: Adverso – t | B28: 4 | C28: 10 | D28: =INDEX('Trayectorias B'!$C$5:$I$45,'B Supuestos'!$C$23+1,6) -> 5423.644 | E28: =D28*(1+'B Supuestos'!$B$12) -> 5863.881 | F28: =INDEX('Trayectorias B'!$C$5:$I$45,'B Supuestos'!$D$23+1,6) -> 5659.3115 | G28: =F28-E28 -> -204.56949 | H28: =IF(G28>0,"Protección","Costo de oportunidad") -> Costo de oportunidad | I28: ='B Supuestos'!$F$23*G28 -> -3133632.9 | J28: ='B Supuestos'!$B$6*SUM(INDEX('Trayectorias B'!$C$5:$I$45,'B Supuestos'!$C$23+2,6):INDEX('Trayectorias B'!$C$5:$I$45,'B Supuestos'!$D$23+1,6)) -> 1.1988166e+08 | K28: =J28-I28 -> 1.2301529e+08 | L28: =4*'B Supuestos'!$B$6*E28 -> 1.1976533e+08 | M28: =J28/L28-1 -> 0.00097125471 | N28: =K28/L28-1 -> 0.027136029 | O28: =K28/(4*'B Supuestos'!$B$6) -> 6023.0034
A29: Base A.1 (mediana) | B29: 1 | C29: 7 | D29: =INDEX('Trayectorias B'!$C$5:$I$45,'B Supuestos'!$C$20+1,7) -> 3708.3529 | E29: =D29*(1+'B Supuestos'!$B$12) -> 4009.3598 | F29: =INDEX('Trayectorias B'!$C$5:$I$45,'B Supuestos'!$D$20+1,7) -> 3779.3936 | G29: =F29-E29 -> -229.96613 | H29: =IF(G29>0,"Protección","Costo de oportunidad") -> Costo de oportunidad | I29: ='B Supuestos'!$F$20*G29 -> -3522663.2 | J29: ='B Supuestos'!$B$6*SUM(INDEX('Trayectorias B'!$C$5:$I$45,'B Supuestos'!$C$20+2,7):INDEX('Trayectorias B'!$C$5:$I$45,'B Supuestos'!$D$20+1,7)) -> 76644998 | K29: =J29-I29 -> 80167661 | L29: =4*'B Supuestos'!$B$6*E29 -> 81888141 | M29: =J29/L29-1 -> -0.064028108 | N29: =K29/L29-1 -> -0.021010118 | O29: =K29/(4*'B Supuestos'!$B$6) -> 3925.1226
A30: Base A.1 (mediana) | B30: 2 | C30: 8 | D30: =INDEX('Trayectorias B'!$C$5:$I$45,'B Supuestos'!$C$21+1,7) -> 3779.3936 | E30: =D30*(1+'B Supuestos'!$B$12) -> 4086.1669 | F30: =INDEX('Trayectorias B'!$C$5:$I$45,'B Supuestos'!$D$21+1,7) -> 3851.7953 | G30: =F30-E30 -> -234.37158 | H30: =IF(G30>0,"Protección","Costo de oportunidad") -> Costo de oportunidad | I30: ='B Supuestos'!$F$21*G30 -> -3590146.7 | J30: ='B Supuestos'!$B$6*SUM(INDEX('Trayectorias B'!$C$5:$I$45,'B Supuestos'!$C$21+2,7):INDEX('Trayectorias B'!$C$5:$I$45,'B Supuestos'!$D$21+1,7)) -> 78113282 | K30: =J30-I30 -> 81703429 | L30: =4*'B Supuestos'!$B$6*E30 -> 83456868 | M30: =J30/L30-1 -> -0.064028108 | N30: =K30/L30-1 -> -0.021010118 | O30: =K30/(4*'B Supuestos'!$B$6) -> 4000.316
A31: Base A.1 (mediana) | B31: 3 | C31: 9 | D31: =INDEX('Trayectorias B'!$C$5:$I$45,'B Supuestos'!$C$22+1,7) -> 3851.7953 | E31: =D31*(1+'B Supuestos'!$B$12) -> 4164.4454 | F31: =INDEX('Trayectorias B'!$C$5:$I$45,'B Supuestos'!$D$22+1,7) -> 3925.5839 | G31: =F31-E31 -> -238.86142 | H31: =IF(G31>0,"Protección","Costo de oportunidad") -> Costo de oportunidad | I31: ='B Supuestos'!$F$22*G31 -> -3658922.9 | J31: ='B Supuestos'!$B$6*SUM(INDEX('Trayectorias B'!$C$5:$I$45,'B Supuestos'!$C$22+2,7):INDEX('Trayectorias B'!$C$5:$I$45,'B Supuestos'!$D$22+1,7)) -> 79609695 | K31: =J31-I31 -> 83268617 | L31: =4*'B Supuestos'!$B$6*E31 -> 85055647 | M31: =J31/L31-1 -> -0.064028108 | N31: =K31/L31-1 -> -0.021010118 | O31: =K31/(4*'B Supuestos'!$B$6) -> 4076.9499
A32: Base A.1 (mediana) | B32: 4 | C32: 10 | D32: =INDEX('Trayectorias B'!$C$5:$I$45,'B Supuestos'!$C$23+1,7) -> 3925.5839 | E32: =D32*(1+'B Supuestos'!$B$12) -> 4244.2234 | F32: =INDEX('Trayectorias B'!$C$5:$I$45,'B Supuestos'!$D$23+1,7) -> 4000.7861 | G32: =F32-E32 -> -243.43728 | H32: =IF(G32>0,"Protección","Costo de oportunidad") -> Costo de oportunidad | I32: ='B Supuestos'!$F$23*G32 -> -3729016.7 | J32: ='B Supuestos'!$B$6*SUM(INDEX('Trayectorias B'!$C$5:$I$45,'B Supuestos'!$C$23+2,7):INDEX('Trayectorias B'!$C$5:$I$45,'B Supuestos'!$D$23+1,7)) -> 81134773 | K32: =J32-I32 -> 84863790 | L32: =4*'B Supuestos'!$B$6*E32 -> 86685053 | M32: =J32/L32-1 -> -0.064028108 | N32: =K32/L32-1 -> -0.021010118 | O32: =K32/(4*'B Supuestos'!$B$6) -> 4155.0518
A35: Parte 2. Resultados de la simulación (20.000 caminos por distribución; los cuatro forwards agrupados)
A36: Indicador | B36: Normal | C36: t de Student (ν = 8,9, estimado) | D36: t de Student de estrés (ν = 4) | E36: Lectura
A37: Proporción con protección (spot al vencimiento > forward) | B37: 0.3252625 | C37: 0.32445 | D37: 0.3065375 | E37: El forward se liquida a favor: sin él, la empresa habría pagado más.
A38: Proporción con costo de oportunidad (spot < forward) | B38: 0.6747375 | C38: 0.67555 | D38: 0.6934625 | E38: El forward se liquida en contra: sin él, la empresa habría pagado menos.
A39: Proporción con pérdida cambiaria extrema (depreciación anual > 20 %) | B39: 0.1057125 | C39: 0.1036 | D39: 0.0915125 | E39: Años con choques como los de 2015 o 2022 (≈ 11 % de los años desde 1999).
A40: Proporción con depreciación anual > 30 % | B40: 0.0304625 | C40: 0.0332875 | D40: 0.0314625 | E40: Cola más extrema: aquí la t de Student pesa más que la normal.
A41: Proporción con apreciación anual > 20 % (costo de oportunidad extremo) | B41: 0.032475 | C41: 0.0324875 | D41: 0.0309625 | E41: Años en los que el forward cuesta mucho frente al spot.
A42: En años extremos: sobrecosto sin cobertura vs spot del pacto | B42: 0.17094047 | C42: 0.17578223 | D42: 0.1843285 | E42: Cuánto más cuestan las cuotas del año frente a la TRM del día del pacto.
A43: En años extremos: sobrecosto con cobertura vs spot del pacto | B43: 0.022500885 | C43: 0.022551756 | D43: 0.019169458 | E43: Con el 75 % cubierto, el sobrecosto se reduce a una fracción.
...

Sheet B.3 Flujo consolidado
A1: B.3 Flujo consolidado del crédito con y sin cobertura
A2: Elija el escenario en la celda amarilla (lista desplegable). Todas las columnas son fórmulas: compra inicial, aporte propio, desembolso, cuotas en USD, conversión a pesos y liquidación de los cuatro NDF.
A4: Escenario | B4: Central – Normal
A5: N.º de columna del escenario | B5: =MATCH(B4,'Trayectorias B'!$C$4:$I$4,0) -> 2
A7: Trimestre | B7: Fecha | C7: Compra de la maquinaria (COP) | D7: Aporte propio (COP) | E7: Desembolso (USD) | F7: TRM | G7: Desembolso (COP) | H7: Cuota (USD) | I7: Cuota (COP) | J7: Forward que vence | K7: TRM al pactar | L7: Forward pactado | M7: Nominal (USD) | N7: Liquidación NDF (COP) | O7: Flujo neto sin cobertura (COP) | P7: Flujo neto con cobertura (COP) | Q7: Flujo del crédito sin cobertura (COP) | R7: Flujo del crédito con cobertura (COP)
A8: 0 | B8: ='Trayectorias TRM'!B5 -> 46313 | C8: =-Supuestos!$B$4 -> -400000000 | D8: =Supuestos!$B$6 -> 40000000 | E8: =Supuestos!$B$9 -> 113397.61 | F8: =INDEX('Trayectorias B'!$C$5:$I$45,1,$B$5) -> 3174.67 | G8: =E8*F8 -> 360000000 | H8: 0 | I8: =H8*F8 -> 0 | J8: =IFERROR(MATCH(A8,'B Supuestos'!$D$20:$D$23,0),"") | K8: =IF(J8="","",INDEX('Trayectorias B'!$C$5:$I$45,A8-3,$B$5)) | L8: =IF(J8="","",K8*(1+'B Supuestos'!$B$12)) | M8: =IF(J8="","",INDEX('B Supuestos'!$F$20:$F$23,J8)) | N8: =IF(J8="",0,M8*(F8-L8)) -> 0 | O8: =C8+D8+G8+I8 -> 0 | P8: =O8+N8 -> 0 | Q8: =G8+I8 -> 360000000 | R8: =Q8+N8 -> 360000000
A9: 1 | B9: ='Trayectorias TRM'!B6 -> 46405 | C9: 0 | D9: 0 | E9: 0 | F9: =INDEX('Trayectorias B'!$C$5:$I$45,2,$B$5) -> 3631.1782 | G9: =E9*F9 -> 0 | H9: =-Amortización!D5 -> -5106.0609 | I9: =H9*F9 -> -18541017 | J9: =IFERROR(MATCH(A9,'B Supuestos'!$D$20:$D$23,0),"") | K9: =IF(J9="","",INDEX('Trayectorias B'!$C$5:$I$45,A9-3,$B$5)) | L9: =IF(J9="","",K9*(1+'B Supuestos'!$B$12)) | M9: =IF(J9="","",INDEX('B Supuestos'!$F$20:$F$23,J9)) | N9: =IF(J9="",0,M9*(F9-L9)) -> 0 | O9: =C9+D9+G9+I9 -> -18541017 | P9: =O9+N9 -> -18541017 | Q9: =G9+I9 -> -18541017 | R9: =Q9+N9 -> -18541017
